[2024-07-09T09:59:58.546+0000] {taskinstance.py:1979} INFO - Dependencies all met for dep_context=non-requeueable deps ti=<TaskInstance: customer_metrics.load_customer_transactions_raw manual__2024-07-09T09:59:47.339590+00:00 [queued]>
[2024-07-09T09:59:58.558+0000] {taskinstance.py:1979} INFO - Dependencies all met for dep_context=requeueable deps ti=<TaskInstance: customer_metrics.load_customer_transactions_raw manual__2024-07-09T09:59:47.339590+00:00 [queued]>
[2024-07-09T09:59:58.559+0000] {taskinstance.py:2193} INFO - Starting attempt 1 of 1
[2024-07-09T09:59:58.577+0000] {taskinstance.py:2214} INFO - Executing <Task(AirbyteTriggerSyncOperator): load_customer_transactions_raw> on 2024-07-09 09:59:47.339590+00:00
[2024-07-09T09:59:58.586+0000] {standard_task_runner.py:60} INFO - Started process 4607 to run task
[2024-07-09T09:59:58.590+0000] {standard_task_runner.py:87} INFO - Running: ['airflow', 'tasks', 'run', 'customer_metrics', 'load_customer_transactions_raw', 'manual__2024-07-09T09:59:47.339590+00:00', '--job-id', '161', '--raw', '--subdir', 'DAGS_FOLDER/customer_metrics.py', '--cfg-path', '/tmp/tmp023xha3s']
[2024-07-09T09:59:58.592+0000] {standard_task_runner.py:88} INFO - Job 161: Subtask load_customer_transactions_raw
[2024-07-09T09:59:58.665+0000] {task_command.py:423} INFO - Running <TaskInstance: customer_metrics.load_customer_transactions_raw manual__2024-07-09T09:59:47.339590+00:00 [running]> on host 3726baa263d6
[2024-07-09T09:59:58.786+0000] {taskinstance.py:2510} INFO - Exporting env vars: AIRFLOW_CTX_DAG_OWNER='airflow' AIRFLOW_CTX_DAG_ID='customer_metrics' AIRFLOW_CTX_TASK_ID='load_customer_transactions_raw' AIRFLOW_CTX_EXECUTION_DATE='2024-07-09T09:59:47.339590+00:00' AIRFLOW_CTX_TRY_NUMBER='1' AIRFLOW_CTX_DAG_RUN_ID='manual__2024-07-09T09:59:47.339590+00:00'
[2024-07-09T09:59:58.802+0000] {base.py:83} INFO - Using connection ID 'airbyte' for task execution.
[2024-07-09T09:59:59.199+0000] {http.py:192} ERROR - HTTP error: Conflict
[2024-07-09T09:59:59.200+0000] {http.py:193} ERROR - {"message":"A sync is already running for: 057d138b-f07c-4803-ba4a-dfbccbdfcb31","exceptionClassName":"io.airbyte.commons.server.errors.ValueConflictKnownException","exceptionStack":["io.airbyte.commons.server.errors.ValueConflictKnownException: A sync is already running for: 057d138b-f07c-4803-ba4a-dfbccbdfcb31","\tat io.airbyte.commons.server.handlers.SchedulerHandler.readJobFromResult(SchedulerHandler.java:811)","\tat io.airbyte.commons.server.handlers.SchedulerHandler.submitManualSyncToWorker(SchedulerHandler.java:781)","\tat io.airbyte.commons.server.handlers.SchedulerHandler.syncConnection(SchedulerHandler.java:570)","\tat io.airbyte.server.apis.ConnectionApiController.lambda$syncConnection$14(ConnectionApiController.java:233)","\tat io.airbyte.server.apis.ApiHelper.execute(ApiHelper.java:28)","\tat io.airbyte.server.apis.ConnectionApiController.syncConnection(ConnectionApiController.java:233)","\tat io.airbyte.server.apis.$ConnectionApiController$Definition$Exec.dispatch(Unknown Source)","\tat io.micronaut.context.AbstractExecutableMethodsDefinition$DispatchedExecutableMethod.invoke(AbstractExecutableMethodsDefinition.java:371)","\tat io.micronaut.context.DefaultBeanContext$4.invoke(DefaultBeanContext.java:594)","\tat io.micronaut.web.router.AbstractRouteMatch.execute(AbstractRouteMatch.java:303)","\tat io.micronaut.web.router.RouteMatch.execute(RouteMatch.java:111)","\tat io.micronaut.http.context.ServerRequestContext.with(ServerRequestContext.java:103)","\tat io.micronaut.http.server.RouteExecutor.lambda$executeRoute$14(RouteExecutor.java:659)","\tat reactor.core.publisher.FluxDeferContextual.subscribe(FluxDeferContextual.java:49)","\tat reactor.core.publisher.InternalFluxOperator.subscribe(InternalFluxOperator.java:62)","\tat reactor.core.publisher.FluxSubscribeOn$SubscribeOnSubscriber.run(FluxSubscribeOn.java:194)","\tat io.micronaut.reactive.reactor.instrument.ReactorInstrumentation.lambda$init$0(ReactorInstrumentation.java:62)","\tat reactor.core.scheduler.WorkerTask.call(WorkerTask.java:84)","\tat reactor.core.scheduler.WorkerTask.call(WorkerTask.java:37)","\tat io.micronaut.scheduling.instrument.InvocationInstrumenterWrappedCallable.call(InvocationInstrumenterWrappedCallable.java:53)","\tat java.base/java.util.concurrent.FutureTask.run(FutureTask.java:317)","\tat java.base/java.util.concurrent.ThreadPoolExecutor.runWorker(ThreadPoolExecutor.java:1144)","\tat java.base/java.util.concurrent.ThreadPoolExecutor$Worker.run(ThreadPoolExecutor.java:642)","\tat java.base/java.lang.Thread.run(Thread.java:1583)"]}
[2024-07-09T09:59:59.219+0000] {taskinstance.py:2728} ERROR - Task failed with exception
Traceback (most recent call last):
  File "/home/airflow/.local/lib/python3.8/site-packages/airflow/providers/http/hooks/http.py", line 190, in check_response
    response.raise_for_status()
  File "/home/airflow/.local/lib/python3.8/site-packages/requests/models.py", line 1021, in raise_for_status
    raise HTTPError(http_error_msg, response=self)
requests.exceptions.HTTPError: 409 Client Error: Conflict for url: http://airbyte-server:8001/api/v1/connections/sync

During handling of the above exception, another exception occurred:

Traceback (most recent call last):
  File "/home/airflow/.local/lib/python3.8/site-packages/airflow/models/taskinstance.py", line 444, in _execute_task
    result = _execute_callable(context=context, **execute_callable_kwargs)
  File "/home/airflow/.local/lib/python3.8/site-packages/airflow/models/taskinstance.py", line 414, in _execute_callable
    return execute_callable(context=context, **execute_callable_kwargs)
  File "/home/airflow/.local/lib/python3.8/site-packages/airflow/providers/airbyte/operators/airbyte.py", line 81, in execute
    job_object = hook.submit_sync_connection(connection_id=self.connection_id)
  File "/home/airflow/.local/lib/python3.8/site-packages/airflow/providers/airbyte/hooks/airbyte.py", line 149, in submit_sync_connection
    return self.run(
  File "/home/airflow/.local/lib/python3.8/site-packages/airflow/providers/http/hooks/http.py", line 180, in run
    return self.run_and_check(session, prepped_request, extra_options)
  File "/home/airflow/.local/lib/python3.8/site-packages/airflow/providers/http/hooks/http.py", line 231, in run_and_check
    self.check_response(response)
  File "/home/airflow/.local/lib/python3.8/site-packages/airflow/providers/http/hooks/http.py", line 194, in check_response
    raise AirflowException(str(response.status_code) + ":" + response.reason)
airflow.exceptions.AirflowException: 409:Conflict
[2024-07-09T09:59:59.226+0000] {taskinstance.py:1149} INFO - Marking task as FAILED. dag_id=customer_metrics, task_id=load_customer_transactions_raw, execution_date=20240709T095947, start_date=20240709T095958, end_date=20240709T095959
[2024-07-09T09:59:59.268+0000] {standard_task_runner.py:107} ERROR - Failed to execute job 161 for task load_customer_transactions_raw (409:Conflict; 4607)
[2024-07-09T09:59:59.290+0000] {local_task_job_runner.py:234} INFO - Task exited with return code 1
[2024-07-09T09:59:59.360+0000] {taskinstance.py:3309} INFO - 0 downstream tasks scheduled from follow-on schedule check
