[2024-07-09T04:44:20.934+0000] {taskinstance.py:1979} INFO - Dependencies all met for dep_context=non-requeueable deps ti=<TaskInstance: customer_metrics.audit_labeled_transactions scheduled__2024-07-08T00:00:00+00:00 [queued]>
[2024-07-09T04:44:20.942+0000] {taskinstance.py:1979} INFO - Dependencies all met for dep_context=requeueable deps ti=<TaskInstance: customer_metrics.audit_labeled_transactions scheduled__2024-07-08T00:00:00+00:00 [queued]>
[2024-07-09T04:44:20.943+0000] {taskinstance.py:2193} INFO - Starting attempt 1 of 1
[2024-07-09T04:44:20.955+0000] {taskinstance.py:2214} INFO - Executing <Task(_PythonExternalDecoratedOperator): audit_labeled_transactions> on 2024-07-08 00:00:00+00:00
[2024-07-09T04:44:20.963+0000] {standard_task_runner.py:60} INFO - Started process 726 to run task
[2024-07-09T04:44:20.965+0000] {standard_task_runner.py:87} INFO - Running: ['airflow', 'tasks', 'run', 'customer_metrics', 'audit_labeled_transactions', 'scheduled__2024-07-08T00:00:00+00:00', '--job-id', '25', '--raw', '--subdir', 'DAGS_FOLDER/customer_metrics.py', '--cfg-path', '/tmp/tmph3a3qkzz']
[2024-07-09T04:44:20.967+0000] {standard_task_runner.py:88} INFO - Job 25: Subtask audit_labeled_transactions
[2024-07-09T04:44:21.015+0000] {task_command.py:423} INFO - Running <TaskInstance: customer_metrics.audit_labeled_transactions scheduled__2024-07-08T00:00:00+00:00 [running]> on host 3726baa263d6
[2024-07-09T04:44:21.098+0000] {taskinstance.py:2510} INFO - Exporting env vars: AIRFLOW_CTX_DAG_OWNER='airflow' AIRFLOW_CTX_DAG_ID='customer_metrics' AIRFLOW_CTX_TASK_ID='audit_labeled_transactions' AIRFLOW_CTX_EXECUTION_DATE='2024-07-08T00:00:00+00:00' AIRFLOW_CTX_TRY_NUMBER='1' AIRFLOW_CTX_DAG_RUN_ID='scheduled__2024-07-08T00:00:00+00:00'
[2024-07-09T04:44:21.143+0000] {python.py:913} WARNING - When checking for Airflow installed in virtual environment got Command '['/opt/airflow/soda_venv/bin/python', '-c', 'from airflow import __version__; print(__version__)']' returned non-zero exit status 1.
[2024-07-09T04:44:21.144+0000] {python.py:914} WARNING - This means that Airflow is not properly installed by  /opt/airflow/soda_venv/bin/python. Airflow context keys will not be available. Please Install Airflow 2.8.2 in your environment to access them.
[2024-07-09T04:44:21.207+0000] {process_utils.py:182} INFO - Executing cmd: /opt/airflow/soda_venv/bin/python /tmp/venv-call4nzybgt_/script.py /tmp/venv-call4nzybgt_/script.in /tmp/venv-call4nzybgt_/script.out /tmp/venv-call4nzybgt_/string_args.txt /tmp/venv-call4nzybgt_/termination.log
[2024-07-09T04:44:21.218+0000] {process_utils.py:186} INFO - Output:
[2024-07-09T04:44:22.975+0000] {process_utils.py:190} INFO - [04:44:22] Could not connect to data source "staging": 251005: User is empty
[2024-07-09T04:44:22.976+0000] {process_utils.py:190} INFO -   | 251005: User is empty
[2024-07-09T04:44:22.976+0000] {process_utils.py:190} INFO -   | Stacktrace:
[2024-07-09T04:44:22.977+0000] {process_utils.py:190} INFO -   | Traceback (most recent call last):
[2024-07-09T04:44:22.977+0000] {process_utils.py:190} INFO -   |   File "/opt/airflow/soda_venv/lib/python3.8/site-packages/soda/execution/data_source_manager.py", line 48, in get_data_source
[2024-07-09T04:44:22.978+0000] {process_utils.py:190} INFO -   |     data_source.connect()
[2024-07-09T04:44:22.978+0000] {process_utils.py:190} INFO -   |   File "/opt/airflow/soda_venv/lib/python3.8/site-packages/soda/data_sources/snowflake_data_source.py", line 100, in connect
[2024-07-09T04:44:22.979+0000] {process_utils.py:190} INFO -   |     self.connection = connector.connect(
[2024-07-09T04:44:22.979+0000] {process_utils.py:190} INFO -   |   File "/opt/airflow/soda_venv/lib/python3.8/site-packages/snowflake/connector/__init__.py", line 55, in Connect
[2024-07-09T04:44:22.980+0000] {process_utils.py:190} INFO -   |     return SnowflakeConnection(**kwargs)
[2024-07-09T04:44:22.980+0000] {process_utils.py:190} INFO -   |   File "/opt/airflow/soda_venv/lib/python3.8/site-packages/snowflake/connector/connection.py", line 442, in __init__
[2024-07-09T04:44:22.980+0000] {process_utils.py:190} INFO -   |     self.connect(**kwargs)
[2024-07-09T04:44:22.981+0000] {process_utils.py:190} INFO -   |   File "/opt/airflow/soda_venv/lib/python3.8/site-packages/snowflake/connector/connection.py", line 707, in connect
[2024-07-09T04:44:22.981+0000] {process_utils.py:190} INFO -   |     self.__config(**kwargs)
[2024-07-09T04:44:22.981+0000] {process_utils.py:190} INFO -   |   File "/opt/airflow/soda_venv/lib/python3.8/site-packages/snowflake/connector/connection.py", line 1188, in __config
[2024-07-09T04:44:22.982+0000] {process_utils.py:190} INFO -   |     Error.errorhandler_wrapper(
[2024-07-09T04:44:22.982+0000] {process_utils.py:190} INFO -   |   File "/opt/airflow/soda_venv/lib/python3.8/site-packages/snowflake/connector/errors.py", line 290, in errorhandler_wrapper
[2024-07-09T04:44:22.983+0000] {process_utils.py:190} INFO -   |     handed_over = Error.hand_to_other_handler(
[2024-07-09T04:44:22.983+0000] {process_utils.py:190} INFO -   |   File "/opt/airflow/soda_venv/lib/python3.8/site-packages/snowflake/connector/errors.py", line 348, in hand_to_other_handler
[2024-07-09T04:44:22.984+0000] {process_utils.py:190} INFO -   |     connection.errorhandler(connection, cursor, error_class, error_value)
[2024-07-09T04:44:22.984+0000] {process_utils.py:190} INFO -   |   File "/opt/airflow/soda_venv/lib/python3.8/site-packages/snowflake/connector/errors.py", line 221, in default_errorhandler
[2024-07-09T04:44:22.984+0000] {process_utils.py:190} INFO -   |     raise error_class(
[2024-07-09T04:44:22.985+0000] {process_utils.py:190} INFO -   | snowflake.connector.errors.ProgrammingError: 251005: User is empty
[2024-07-09T04:44:22.985+0000] {process_utils.py:190} INFO - 
[2024-07-09T04:44:22.985+0000] {process_utils.py:190} INFO - [04:44:22] No valid checks found, 0 checks evaluated.
[2024-07-09T04:44:22.986+0000] {process_utils.py:190} INFO - [04:44:22] Could not connect to data source "staging": 251005: User is empty
[2024-07-09T04:44:22.986+0000] {process_utils.py:190} INFO -   | 251005: User is empty
[2024-07-09T04:44:22.986+0000] {process_utils.py:190} INFO -   | Stacktrace:
[2024-07-09T04:44:22.986+0000] {process_utils.py:190} INFO -   | Traceback (most recent call last):
[2024-07-09T04:44:22.987+0000] {process_utils.py:190} INFO -   |   File "/opt/airflow/soda_venv/lib/python3.8/site-packages/soda/execution/data_source_manager.py", line 48, in get_data_source
[2024-07-09T04:44:22.987+0000] {process_utils.py:190} INFO -   |     data_source.connect()
[2024-07-09T04:44:22.987+0000] {process_utils.py:190} INFO -   |   File "/opt/airflow/soda_venv/lib/python3.8/site-packages/soda/data_sources/snowflake_data_source.py", line 100, in connect
[2024-07-09T04:44:22.988+0000] {process_utils.py:190} INFO -   |     self.connection = connector.connect(
[2024-07-09T04:44:22.988+0000] {process_utils.py:190} INFO -   |   File "/opt/airflow/soda_venv/lib/python3.8/site-packages/snowflake/connector/__init__.py", line 55, in Connect
[2024-07-09T04:44:22.988+0000] {process_utils.py:190} INFO -   |     return SnowflakeConnection(**kwargs)
[2024-07-09T04:44:22.989+0000] {process_utils.py:190} INFO -   |   File "/opt/airflow/soda_venv/lib/python3.8/site-packages/snowflake/connector/connection.py", line 442, in __init__
[2024-07-09T04:44:22.989+0000] {process_utils.py:190} INFO -   |     self.connect(**kwargs)
[2024-07-09T04:44:22.989+0000] {process_utils.py:190} INFO -   |   File "/opt/airflow/soda_venv/lib/python3.8/site-packages/snowflake/connector/connection.py", line 707, in connect
[2024-07-09T04:44:22.989+0000] {process_utils.py:190} INFO -   |     self.__config(**kwargs)
[2024-07-09T04:44:22.990+0000] {process_utils.py:190} INFO -   |   File "/opt/airflow/soda_venv/lib/python3.8/site-packages/snowflake/connector/connection.py", line 1188, in __config
[2024-07-09T04:44:22.990+0000] {process_utils.py:190} INFO -   |     Error.errorhandler_wrapper(
[2024-07-09T04:44:22.990+0000] {process_utils.py:190} INFO -   |   File "/opt/airflow/soda_venv/lib/python3.8/site-packages/snowflake/connector/errors.py", line 290, in errorhandler_wrapper
[2024-07-09T04:44:22.991+0000] {process_utils.py:190} INFO -   |     handed_over = Error.hand_to_other_handler(
[2024-07-09T04:44:22.991+0000] {process_utils.py:190} INFO -   |   File "/opt/airflow/soda_venv/lib/python3.8/site-packages/snowflake/connector/errors.py", line 348, in hand_to_other_handler
[2024-07-09T04:44:22.992+0000] {process_utils.py:190} INFO -   |     connection.errorhandler(connection, cursor, error_class, error_value)
[2024-07-09T04:44:22.992+0000] {process_utils.py:190} INFO -   |   File "/opt/airflow/soda_venv/lib/python3.8/site-packages/snowflake/connector/errors.py", line 221, in default_errorhandler
[2024-07-09T04:44:22.992+0000] {process_utils.py:190} INFO -   |     raise error_class(
[2024-07-09T04:44:22.993+0000] {process_utils.py:190} INFO -   | snowflake.connector.errors.ProgrammingError: 251005: User is empty
[2024-07-09T04:44:22.993+0000] {process_utils.py:190} INFO - 
[2024-07-09T04:44:22.993+0000] {process_utils.py:190} INFO - Running Soda Scan ...
[2024-07-09T04:44:22.994+0000] {process_utils.py:190} INFO - INFO   | Soda Core 3.2.2
[2024-07-09T04:44:22.994+0000] {process_utils.py:190} INFO - DEBUG  | Reading configuration file "include/soda/configuration.yml"
[2024-07-09T04:44:22.994+0000] {process_utils.py:190} INFO - DEBUG  | Reading SodaCL file "include/soda/checks/tables/labeled_transactions.yml"
[2024-07-09T04:44:22.995+0000] {process_utils.py:190} INFO - DEBUG  | Reading SodaCL file "include/soda/checks/tables/customer_transactions.yml"
[2024-07-09T04:44:22.996+0000] {process_utils.py:190} INFO - DEBUG  | Scan execution starts
[2024-07-09T04:44:22.996+0000] {process_utils.py:190} INFO - ERROR  | Could not connect to data source "staging": 251005: User is empty | 251005: User is empty
[2024-07-09T04:44:22.997+0000] {process_utils.py:190} INFO - INFO   | Scan summary:
[2024-07-09T04:44:22.997+0000] {process_utils.py:190} INFO - WARNING| No valid checks found, 0 checks evaluated.
[2024-07-09T04:44:22.998+0000] {process_utils.py:190} INFO - INFO   | 1 errors.
[2024-07-09T04:44:22.999+0000] {process_utils.py:190} INFO - INFO   | Oops! 1 error. 0 failures. 0 warnings. 0 pass.
[2024-07-09T04:44:22.999+0000] {process_utils.py:190} INFO - Traceback (most recent call last):
[2024-07-09T04:44:22.999+0000] {process_utils.py:190} INFO -   File "/tmp/venv-call4nzybgt_/script.py", line 48, in <module>
[2024-07-09T04:44:23.000+0000] {process_utils.py:190} INFO -     res = audit_labeled_transactions(*arg_dict["args"], **arg_dict["kwargs"])
[2024-07-09T04:44:23.000+0000] {process_utils.py:190} INFO -   File "/tmp/venv-call4nzybgt_/script.py", line 21, in audit_labeled_transactions
[2024-07-09T04:44:23.000+0000] {process_utils.py:190} INFO -     check(scan_name, checks_subpath, data_source)
[2024-07-09T04:44:23.001+0000] {process_utils.py:190} INFO -   File "/opt/airflow/include/soda/helpers.py", line 22, in check
[2024-07-09T04:44:23.001+0000] {process_utils.py:190} INFO -     raise ValueError('Soda Scan failed')
[2024-07-09T04:44:23.001+0000] {process_utils.py:190} INFO - ValueError: Soda Scan failed
[2024-07-09T04:44:23.172+0000] {taskinstance.py:2728} ERROR - Task failed with exception
Traceback (most recent call last):
  File "/home/airflow/.local/lib/python3.8/site-packages/airflow/models/taskinstance.py", line 444, in _execute_task
    result = _execute_callable(context=context, **execute_callable_kwargs)
  File "/home/airflow/.local/lib/python3.8/site-packages/airflow/models/taskinstance.py", line 414, in _execute_callable
    return execute_callable(context=context, **execute_callable_kwargs)
  File "/home/airflow/.local/lib/python3.8/site-packages/airflow/decorators/base.py", line 241, in execute
    return_value = super().execute(context)
  File "/home/airflow/.local/lib/python3.8/site-packages/airflow/operators/python.py", line 401, in execute
    return super().execute(context=serializable_context)
  File "/home/airflow/.local/lib/python3.8/site-packages/airflow/operators/python.py", line 200, in execute
    return_value = self.execute_callable()
  File "/home/airflow/.local/lib/python3.8/site-packages/airflow/operators/python.py", line 861, in execute_callable
    return self._execute_python_callable_in_subprocess(python_path)
  File "/home/airflow/.local/lib/python3.8/site-packages/airflow/operators/python.py", line 478, in _execute_python_callable_in_subprocess
    raise AirflowException(error_msg) from None
airflow.exceptions.AirflowException: Process returned non-zero exit status 1.
Soda Scan failed
[2024-07-09T04:44:23.178+0000] {taskinstance.py:1149} INFO - Marking task as FAILED. dag_id=customer_metrics, task_id=audit_labeled_transactions, execution_date=20240708T000000, start_date=20240709T044420, end_date=20240709T044423
[2024-07-09T04:44:23.195+0000] {standard_task_runner.py:107} ERROR - Failed to execute job 25 for task audit_labeled_transactions (Process returned non-zero exit status 1.
Soda Scan failed; 726)
[2024-07-09T04:44:23.228+0000] {local_task_job_runner.py:234} INFO - Task exited with return code 1
[2024-07-09T04:44:23.254+0000] {taskinstance.py:3309} INFO - 0 downstream tasks scheduled from follow-on schedule check
[2024-07-09T10:01:09.744+0000] {taskinstance.py:1979} INFO - Dependencies all met for dep_context=non-requeueable deps ti=<TaskInstance: customer_metrics.audit_labeled_transactions scheduled__2024-07-08T00:00:00+00:00 [queued]>
[2024-07-09T10:01:09.756+0000] {taskinstance.py:1979} INFO - Dependencies all met for dep_context=requeueable deps ti=<TaskInstance: customer_metrics.audit_labeled_transactions scheduled__2024-07-08T00:00:00+00:00 [queued]>
[2024-07-09T10:01:09.756+0000] {taskinstance.py:2193} INFO - Starting attempt 1 of 1
[2024-07-09T10:01:09.770+0000] {taskinstance.py:2214} INFO - Executing <Task(_PythonExternalDecoratedOperator): audit_labeled_transactions> on 2024-07-08 00:00:00+00:00
[2024-07-09T10:01:09.778+0000] {standard_task_runner.py:60} INFO - Started process 4856 to run task
[2024-07-09T10:01:09.781+0000] {standard_task_runner.py:87} INFO - Running: ['airflow', 'tasks', 'run', 'customer_metrics', 'audit_labeled_transactions', 'scheduled__2024-07-08T00:00:00+00:00', '--job-id', '166', '--raw', '--subdir', 'DAGS_FOLDER/customer_metrics.py', '--cfg-path', '/tmp/tmpi8suffut']
[2024-07-09T10:01:09.784+0000] {standard_task_runner.py:88} INFO - Job 166: Subtask audit_labeled_transactions
[2024-07-09T10:01:09.839+0000] {task_command.py:423} INFO - Running <TaskInstance: customer_metrics.audit_labeled_transactions scheduled__2024-07-08T00:00:00+00:00 [running]> on host 3726baa263d6
[2024-07-09T10:01:09.923+0000] {taskinstance.py:2510} INFO - Exporting env vars: AIRFLOW_CTX_DAG_OWNER='airflow' AIRFLOW_CTX_DAG_ID='customer_metrics' AIRFLOW_CTX_TASK_ID='audit_labeled_transactions' AIRFLOW_CTX_EXECUTION_DATE='2024-07-08T00:00:00+00:00' AIRFLOW_CTX_TRY_NUMBER='1' AIRFLOW_CTX_DAG_RUN_ID='scheduled__2024-07-08T00:00:00+00:00'
[2024-07-09T10:01:09.962+0000] {python.py:913} WARNING - When checking for Airflow installed in virtual environment got Command '['/opt/airflow/soda_venv/bin/python', '-c', 'from airflow import __version__; print(__version__)']' returned non-zero exit status 1.
[2024-07-09T10:01:09.964+0000] {python.py:914} WARNING - This means that Airflow is not properly installed by  /opt/airflow/soda_venv/bin/python. Airflow context keys will not be available. Please Install Airflow 2.8.2 in your environment to access them.
[2024-07-09T10:01:10.027+0000] {process_utils.py:182} INFO - Executing cmd: /opt/airflow/soda_venv/bin/python /tmp/venv-callypg2har3/script.py /tmp/venv-callypg2har3/script.in /tmp/venv-callypg2har3/script.out /tmp/venv-callypg2har3/string_args.txt /tmp/venv-callypg2har3/termination.log
[2024-07-09T10:01:10.039+0000] {process_utils.py:186} INFO - Output:
[2024-07-09T10:01:13.776+0000] {process_utils.py:190} INFO - Running Soda Scan ...
[2024-07-09T10:01:13.777+0000] {process_utils.py:190} INFO - INFO   | Soda Core 3.2.2
[2024-07-09T10:01:13.777+0000] {process_utils.py:190} INFO - DEBUG  | Reading configuration file "include/soda/configuration.yml"
[2024-07-09T10:01:13.778+0000] {process_utils.py:190} INFO - DEBUG  | Reading SodaCL file "include/soda/checks/tables/labeled_transactions.yml"
[2024-07-09T10:01:13.778+0000] {process_utils.py:190} INFO - DEBUG  | Reading SodaCL file "include/soda/checks/tables/customer_transactions.yml"
[2024-07-09T10:01:13.779+0000] {process_utils.py:190} INFO - DEBUG  | Scan execution starts
[2024-07-09T10:01:13.780+0000] {process_utils.py:190} INFO - DEBUG  | Query staging.customer_transactions.aggregation[0]:
[2024-07-09T10:01:13.780+0000] {process_utils.py:190} INFO - SELECT
[2024-07-09T10:01:13.781+0000] {process_utils.py:190} INFO -   COUNT(*),
[2024-07-09T10:01:13.781+0000] {process_utils.py:190} INFO -   COUNT(CASE WHEN transaction_id IS NULL THEN 1 END),
[2024-07-09T10:01:13.782+0000] {process_utils.py:190} INFO -   COUNT(CASE WHEN user_id IS NULL THEN 1 END),
[2024-07-09T10:01:13.783+0000] {process_utils.py:190} INFO -   COUNT(CASE WHEN transaction_date IS NULL THEN 1 END),
[2024-07-09T10:01:13.783+0000] {process_utils.py:190} INFO -   COUNT(CASE WHEN amount IS NULL THEN 1 END)
[2024-07-09T10:01:13.783+0000] {process_utils.py:190} INFO - FROM AIRBYTE_DATABASE.STAGING.customer_transactions
[2024-07-09T10:01:13.784+0000] {process_utils.py:190} INFO - DEBUG  | Query staging.customer_transactions.transaction_id.duplicate_count:
[2024-07-09T10:01:13.784+0000] {process_utils.py:190} INFO - 
[2024-07-09T10:01:13.785+0000] {process_utils.py:190} INFO - WITH frequencies AS (
[2024-07-09T10:01:13.785+0000] {process_utils.py:190} INFO -     SELECT COUNT(*) AS frequency
[2024-07-09T10:01:13.785+0000] {process_utils.py:190} INFO -     FROM AIRBYTE_DATABASE.STAGING.customer_transactions
[2024-07-09T10:01:13.786+0000] {process_utils.py:190} INFO -     WHERE transaction_id IS NOT NULL
[2024-07-09T10:01:13.786+0000] {process_utils.py:190} INFO -     GROUP BY transaction_id)
[2024-07-09T10:01:13.786+0000] {process_utils.py:190} INFO - SELECT COUNT(*)
[2024-07-09T10:01:13.786+0000] {process_utils.py:190} INFO - FROM frequencies
[2024-07-09T10:01:13.787+0000] {process_utils.py:190} INFO - WHERE frequency > 1
[2024-07-09T10:01:13.787+0000] {process_utils.py:190} INFO - DEBUG  | Query staging.customer_transactions.duplicate_count[transaction_id].failed_rows.aggregated:
[2024-07-09T10:01:13.787+0000] {process_utils.py:190} INFO - 
[2024-07-09T10:01:13.788+0000] {process_utils.py:190} INFO - WITH frequencies AS (
[2024-07-09T10:01:13.788+0000] {process_utils.py:190} INFO -     SELECT transaction_id, COUNT(*) AS frequency
[2024-07-09T10:01:13.788+0000] {process_utils.py:190} INFO -     FROM AIRBYTE_DATABASE.STAGING.customer_transactions
[2024-07-09T10:01:13.789+0000] {process_utils.py:190} INFO -     WHERE transaction_id IS NOT NULL
[2024-07-09T10:01:13.789+0000] {process_utils.py:190} INFO -     GROUP BY transaction_id)
[2024-07-09T10:01:13.789+0000] {process_utils.py:190} INFO - SELECT *
[2024-07-09T10:01:13.790+0000] {process_utils.py:190} INFO - FROM frequencies
[2024-07-09T10:01:13.790+0000] {process_utils.py:190} INFO - WHERE frequency > 1
[2024-07-09T10:01:13.791+0000] {process_utils.py:190} INFO - ORDER BY frequency DESC
[2024-07-09T10:01:13.791+0000] {process_utils.py:190} INFO - LIMIT 100
[2024-07-09T10:01:13.791+0000] {process_utils.py:190} INFO - DEBUG  | Query staging.customer_transactions.schema[customer_transactions]:
[2024-07-09T10:01:13.792+0000] {process_utils.py:190} INFO - SELECT column_name, data_type, is_nullable
[2024-07-09T10:01:13.792+0000] {process_utils.py:190} INFO - FROM information_schema.columns
[2024-07-09T10:01:13.792+0000] {process_utils.py:190} INFO - WHERE upper(table_name) = 'CUSTOMER_TRANSACTIONS'
[2024-07-09T10:01:13.793+0000] {process_utils.py:190} INFO -   AND upper(table_catalog) = 'AIRBYTE_DATABASE'
[2024-07-09T10:01:13.793+0000] {process_utils.py:190} INFO -   AND upper(table_schema) = 'STAGING'
[2024-07-09T10:01:13.793+0000] {process_utils.py:190} INFO - ORDER BY ORDINAL_POSITION
[2024-07-09T10:01:13.794+0000] {process_utils.py:190} INFO - INFO   | Scan summary:
[2024-07-09T10:01:13.794+0000] {process_utils.py:190} INFO - DEBUG  | 4/4 queries OK
[2024-07-09T10:01:13.794+0000] {process_utils.py:190} INFO - DEBUG  |   staging.customer_transactions.aggregation[0] [OK] 0:00:00.093242
[2024-07-09T10:01:13.795+0000] {process_utils.py:190} INFO - DEBUG  |   staging.customer_transactions.transaction_id.duplicate_count [OK] 0:00:00.074768
[2024-07-09T10:01:13.795+0000] {process_utils.py:190} INFO - DEBUG  |   staging.customer_transactions.duplicate_count[transaction_id].failed_rows.aggregated [OK] 0:00:00.058958
[2024-07-09T10:01:13.795+0000] {process_utils.py:190} INFO - DEBUG  |   staging.customer_transactions.schema[customer_transactions] [OK] 0:00:00.937269
[2024-07-09T10:01:13.796+0000] {process_utils.py:190} INFO - INFO   | 12/14 checks PASSED:
[2024-07-09T10:01:13.796+0000] {process_utils.py:190} INFO - INFO   |     customer_transactions in staging
[2024-07-09T10:01:13.796+0000] {process_utils.py:190} INFO - INFO   |       Schema Check [include/soda/checks/tables/labeled_transactions.yml] [PASSED]
[2024-07-09T10:01:13.797+0000] {process_utils.py:190} INFO - INFO   |         schema_measured = [_AIRBYTE_RAW_ID TEXT, _AIRBYTE_EXTRACTED_AT TIMESTAMP_TZ, _AIRBYTE_META VARIANT, AMOUNT FLOAT, USER_ID NUMBER, TRANSACTION_ID NUMBER, TRANSACTION_DATE TEXT, _AB_SOURCE_FILE_URL TEXT, _AB_SOURCE_FILE_LAST_MODIFIED TEXT]
[2024-07-09T10:01:13.797+0000] {process_utils.py:190} INFO - INFO   |       Schema Check [include/soda/checks/tables/customer_transactions.yml] [PASSED]
[2024-07-09T10:01:13.798+0000] {process_utils.py:190} INFO - INFO   |         schema_measured = [_AIRBYTE_RAW_ID TEXT, _AIRBYTE_EXTRACTED_AT TIMESTAMP_TZ, _AIRBYTE_META VARIANT, AMOUNT FLOAT, USER_ID NUMBER, TRANSACTION_ID NUMBER, TRANSACTION_DATE TEXT, _AB_SOURCE_FILE_URL TEXT, _AB_SOURCE_FILE_LAST_MODIFIED TEXT]
[2024-07-09T10:01:13.798+0000] {process_utils.py:190} INFO - INFO   |       Duplicate transaction IDs [include/soda/checks/tables/labeled_transactions.yml] [PASSED]
[2024-07-09T10:01:13.798+0000] {process_utils.py:190} INFO - INFO   |         check_value: 0
[2024-07-09T10:01:13.799+0000] {process_utils.py:190} INFO - INFO   |       Transaction IDs cannot be null [include/soda/checks/tables/labeled_transactions.yml] [PASSED]
[2024-07-09T10:01:13.799+0000] {process_utils.py:190} INFO - INFO   |         check_value: 0
[2024-07-09T10:01:13.799+0000] {process_utils.py:190} INFO - INFO   |       Duplicate transaction ids [include/soda/checks/tables/customer_transactions.yml] [PASSED]
[2024-07-09T10:01:13.800+0000] {process_utils.py:190} INFO - INFO   |         check_value: 0
[2024-07-09T10:01:13.816+0000] {process_utils.py:190} INFO - INFO   |       Transactions ids missing in customer_transactions [include/soda/checks/tables/customer_transactions.yml] [PASSED]
[2024-07-09T10:01:13.818+0000] {process_utils.py:190} INFO - INFO   |         check_value: 0
[2024-07-09T10:01:13.819+0000] {process_utils.py:190} INFO - INFO   |       User IDs cannot be null [include/soda/checks/tables/labeled_transactions.yml] [PASSED]
[2024-07-09T10:01:13.820+0000] {process_utils.py:190} INFO - INFO   |         check_value: 0
[2024-07-09T10:01:13.821+0000] {process_utils.py:190} INFO - INFO   |       User ids missing in customer_transactions [include/soda/checks/tables/customer_transactions.yml] [PASSED]
[2024-07-09T10:01:13.821+0000] {process_utils.py:190} INFO - INFO   |         check_value: 0
[2024-07-09T10:01:13.822+0000] {process_utils.py:190} INFO - INFO   |       Transaction date cannot be null [include/soda/checks/tables/labeled_transactions.yml] [PASSED]
[2024-07-09T10:01:13.822+0000] {process_utils.py:190} INFO - INFO   |         check_value: 0
[2024-07-09T10:01:13.823+0000] {process_utils.py:190} INFO - INFO   |       transaction_date missing in customer_transactions [include/soda/checks/tables/customer_transactions.yml] [PASSED]
[2024-07-09T10:01:13.824+0000] {process_utils.py:190} INFO - INFO   |         check_value: 0
[2024-07-09T10:01:13.825+0000] {process_utils.py:190} INFO - INFO   |       Amount cannot be null [include/soda/checks/tables/labeled_transactions.yml] [PASSED]
[2024-07-09T10:01:13.825+0000] {process_utils.py:190} INFO - INFO   |         check_value: 0
[2024-07-09T10:01:13.826+0000] {process_utils.py:190} INFO - INFO   |       amount missing in customer_transactions [include/soda/checks/tables/customer_transactions.yml] [PASSED]
[2024-07-09T10:01:13.827+0000] {process_utils.py:190} INFO - INFO   |         check_value: 0
[2024-07-09T10:01:13.827+0000] {process_utils.py:190} INFO - INFO   | 2/14 checks FAILED:
[2024-07-09T10:01:13.828+0000] {process_utils.py:190} INFO - INFO   |     customer_transactions in staging
[2024-07-09T10:01:13.829+0000] {process_utils.py:190} INFO - INFO   |       Table is empty [include/soda/checks/tables/labeled_transactions.yml] [FAILED]
[2024-07-09T10:01:13.830+0000] {process_utils.py:190} INFO - INFO   |         check_value: 0
[2024-07-09T10:01:13.830+0000] {process_utils.py:190} INFO - INFO   |       Table is empty [include/soda/checks/tables/customer_transactions.yml] [FAILED]
[2024-07-09T10:01:13.831+0000] {process_utils.py:190} INFO - INFO   |         check_value: 0
[2024-07-09T10:01:13.831+0000] {process_utils.py:190} INFO - INFO   | Oops! 2 failures. 0 warnings. 0 errors. 12 pass.
[2024-07-09T10:01:13.832+0000] {process_utils.py:190} INFO - Traceback (most recent call last):
[2024-07-09T10:01:13.833+0000] {process_utils.py:190} INFO -   File "/tmp/venv-callypg2har3/script.py", line 48, in <module>
[2024-07-09T10:01:13.833+0000] {process_utils.py:190} INFO -     res = audit_labeled_transactions(*arg_dict["args"], **arg_dict["kwargs"])
[2024-07-09T10:01:13.834+0000] {process_utils.py:190} INFO -   File "/tmp/venv-callypg2har3/script.py", line 21, in audit_labeled_transactions
[2024-07-09T10:01:13.834+0000] {process_utils.py:190} INFO -     check(scan_name, checks_subpath, data_source)
[2024-07-09T10:01:13.835+0000] {process_utils.py:190} INFO -   File "/opt/airflow/include/soda/helpers.py", line 22, in check
[2024-07-09T10:01:13.835+0000] {process_utils.py:190} INFO -     raise ValueError('Soda Scan failed')
[2024-07-09T10:01:13.836+0000] {process_utils.py:190} INFO - ValueError: Soda Scan failed
[2024-07-09T10:01:13.986+0000] {taskinstance.py:2728} ERROR - Task failed with exception
Traceback (most recent call last):
  File "/home/airflow/.local/lib/python3.8/site-packages/airflow/models/taskinstance.py", line 444, in _execute_task
    result = _execute_callable(context=context, **execute_callable_kwargs)
  File "/home/airflow/.local/lib/python3.8/site-packages/airflow/models/taskinstance.py", line 414, in _execute_callable
    return execute_callable(context=context, **execute_callable_kwargs)
  File "/home/airflow/.local/lib/python3.8/site-packages/airflow/decorators/base.py", line 241, in execute
    return_value = super().execute(context)
  File "/home/airflow/.local/lib/python3.8/site-packages/airflow/operators/python.py", line 401, in execute
    return super().execute(context=serializable_context)
  File "/home/airflow/.local/lib/python3.8/site-packages/airflow/operators/python.py", line 200, in execute
    return_value = self.execute_callable()
  File "/home/airflow/.local/lib/python3.8/site-packages/airflow/operators/python.py", line 861, in execute_callable
    return self._execute_python_callable_in_subprocess(python_path)
  File "/home/airflow/.local/lib/python3.8/site-packages/airflow/operators/python.py", line 478, in _execute_python_callable_in_subprocess
    raise AirflowException(error_msg) from None
airflow.exceptions.AirflowException: Process returned non-zero exit status 1.
Soda Scan failed
[2024-07-09T10:01:13.989+0000] {taskinstance.py:1149} INFO - Marking task as FAILED. dag_id=customer_metrics, task_id=audit_labeled_transactions, execution_date=20240708T000000, start_date=20240709T100109, end_date=20240709T100113
[2024-07-09T10:01:14.005+0000] {standard_task_runner.py:107} ERROR - Failed to execute job 166 for task audit_labeled_transactions (Process returned non-zero exit status 1.
Soda Scan failed; 4856)
[2024-07-09T10:01:14.051+0000] {local_task_job_runner.py:234} INFO - Task exited with return code 1
[2024-07-09T10:01:14.076+0000] {taskinstance.py:3309} INFO - 0 downstream tasks scheduled from follow-on schedule check
